Workbook

Sheet Income_Clean
A1: Metro Area | B1: Median Household Income | C1: Income Year
A2: Abilene, TX Metro Area | B2: 67328 | C2: 2024
A3: Aguadilla, PR Metro Area | B3: 22398 | C3: 2024
A4: Akron, OH Metro Area | B4: 72371 | C4: 2024
A5: Albany, GA Metro Area | B5: 56906 | C5: 2024
A6: Albany, OR Metro Area | B6: 76329 | C6: 2024
A7: Albany-Schenectady-Troy, NY Metro Area | B7: 88074 | C7: 2024
A8: Albuquerque, NM Metro Area | B8: 70783 | C8: 2024
A9: Alexandria, LA Metro Area | B9: 56353 | C9: 2024
A10: Allentown-Bethlehem-Easton, PA-NJ Metro Area | B10: 84587 | C10: 2024
A11: Altoona, PA Metro Area | B11: 62382 | C11: 2024
A12: Amarillo, TX Metro Area | B12: 69611 | C12: 2024
A13: Ames, IA Metro Area | B13: 73127 | C13: 2024
... A394: Yuma, AZ Metro Area | B394: 62876 | C394: 2024

Sheet Metro_Crosswalk
A1: Zillow Metro | B1: Census Metro | C1: Match Status | D1: Zillow City | E1: Census Match Candidate | F1: Zillow State | G1: Match Check
A2: York, PA | B2: York-Hanover, PA Metro Area | C2: Verified | D2: =LEFT(A2,FIND(",",A2)-1) -> York | E2: =IFERROR(INDEX(Census_Metro_List!$A:$A,MATCH(D2&"*",Census_Metro_List!$A:$A,0)),"No Match") -> York-Hanover, PA Metro Area | F2: =TRIM(RIGHT(A2,LEN(A2)-FIND(",",A2))) -> PA | G2: =IF(E2="No Match","Review",IF(ISNUMBER(SEARCH(F2,E2)),"Likely Match","Review")) -> Likely Match
A3: Philadelphia, PA | B3: Philadelphia-Camden-Wilmington, PA-NJ-DE-MD Metro Area | C3: Verified | D3: =LEFT(A3,FIND(",",A3)-1) -> Philadelphia | E3: =IFERROR(INDEX(Census_Metro_List!$A:$A,MATCH(D3&"*",Census_Metro_List!$A:$A,0)),"No Match") -> Philadelphia-Camden-Wilmington, PA-NJ-DE-MD Metro Area | F3: =TRIM(RIGHT(A3,LEN(A3)-FIND(",",A3))) -> PA | G3: =IF(E3="No Match","Review",IF(ISNUMBER(SEARCH(F3,E3)),"Likely Match","Review")) -> Likely Match
A4: Miami, FL | B4: Miami-Fort Lauderdale-West Palm Beach, FL Metro Area | C4: Verified | D4: =LEFT(A4,FIND(",",A4)-1) -> Miami | E4: =IFERROR(INDEX(Census_Metro_List!$A:$A,MATCH(D4&"*",Census_Metro_List!$A:$A,0)),"No Match") -> Miami-Fort Lauderdale-West Palm Beach, FL Metro Area | F4: =TRIM(RIGHT(A4,LEN(A4)-FIND(",",A4))) -> FL | G4: =IF(E4="No Match","Review",IF(ISNUMBER(SEARCH(F4,E4)),"Likely Match","Review")) -> Likely Match
A5: New York, NY | B5: New York-Newark-Jersey City, NY-NJ Metro Area | C5: Verified | D5: =LEFT(A5,FIND(",",A5)-1) -> New York | E5: =IFERROR(INDEX(Census_Metro_List!$A:$A,MATCH(D5&"*",Census_Metro_List!$A:$A,0)),"No Match") -> New York-Newark-Jersey City, NY-NJ Metro Area | F5: =TRIM(RIGHT(A5,LEN(A5)-FIND(",",A5))) -> NY | G5: =IF(E5="No Match","Review",IF(ISNUMBER(SEARCH(F5,E5)),"Likely Match","Review")) -> Likely Match
A6: Los Angeles, CA | B6: Los Angeles-Long Beach-Anaheim, CA Metro Area | C6: Verified | D6: =LEFT(A6,FIND(",",A6)-1) -> Los Angeles | E6: =IFERROR(INDEX(Census_Metro_List!$A:$A,MATCH(D6&"*",Census_Metro_List!$A:$A,0)),"No Match") -> Los Angeles-Long Beach-Anaheim, CA Metro Area | F6: =TRIM(RIGHT(A6,LEN(A6)-FIND(",",A6))) -> CA | G6: =IF(E6="No Match","Review",IF(ISNUMBER(SEARCH(F6,E6)),"Likely Match","Review")) -> Likely Match
A7: Chicago, IL | B7: Chicago-Naperville-Elgin, IL-IN Metro Area | C7: High Confidence | D7: =LEFT(A7,FIND(",",A7)-1) -> Chicago | E7: =IFERROR(INDEX(Census_Metro_List!$A:$A,MATCH(D7&"*",Census_Metro_List!$A:$A,0)),"No Match") -> Chicago-Naperville-Elgin, IL-IN Metro Area | F7: =TRIM(RIGHT(A7,LEN(A7)-FIND(",",A7))) -> IL | G7: =IF(E7="No Match","Review",IF(ISNUMBER(SEARCH(F7,E7)),"Likely Match","Review")) -> Likely Match
A8: Dallas, TX | B8: Dallas-Fort Worth-Arlington, TX Metro Area | C8: High Confidence | D8: =LEFT(A8,FIND(",",A8)-1) -> Dallas | E8: =IFERROR(INDEX(Census_Metro_List!$A:$A,MATCH(D8&"*",Census_Metro_List!$A:$A,0)),"No Match") -> Dallas-Fort Worth-Arlington, TX Metro Area | F8: =TRIM(RIGHT(A8,LEN(A8)-FIND(",",A8))) -> TX | G8: =IF(E8="No Match","Review",IF(ISNUMBER(SEARCH(F8,E8)),"Likely Match","Review")) -> Likely Match
A9: Houston, TX | B9: Houston-Pasadena-The Woodlands, TX Metro Area | C9: High Confidence | D9: =LEFT(A9,FIND(",",A9)-1) -> Houston | E9: =IFERROR(INDEX(Census_Metro_List!$A:$A,MATCH(D9&"*",Census_Metro_List!$A:$A,0)),"No Match") -> Houston-Pasadena-The Woodlands, TX Metro Area | F9: =TRIM(RIGHT(A9,LEN(A9)-FIND(",",A9))) -> TX | G9: =IF(E9="No Match","Review",IF(ISNUMBER(SEARCH(F9,E9)),"Likely Match","Review")) -> Likely Match
A10: Washington, DC | B10: Washington-Arlington-Alexandria, DC-VA-MD-WV Metro Area | C10: High Confidence | D10: =LEFT(A10,FIND(",",A10)-1) -> Washington | E10: =IFERROR(INDEX(Census_Metro_List!$A:$A,MATCH(D10&"*",Census_Metro_List!$A:$A,0)),"No Match") -> Washington-Arlington-Alexandria, DC-VA-MD-WV Metro Area | F10: =TRIM(RIGHT(A10,LEN(A10)-FIND(",",A10))) -> DC | G10: =IF(E10="No Match","Review",IF(ISNUMBER(SEARCH(F10,E10)),"Likely Match","Review")) -> Likely Match
A11: Atlanta, GA | B11: Atlanta-Sandy Springs-Roswell, GA Metro Area | C11: High Confidence | D11: =LEFT(A11,FIND(",",A11)-1) -> Atlanta | E11: =IFERROR(INDEX(Census_Metro_List!$A:$A,MATCH(D11&"*",Census_Metro_List!$A:$A,0)),"No Match") -> Atlanta-Sandy Springs-Roswell, GA Metro Area | F11: =TRIM(RIGHT(A11,LEN(A11)-FIND(",",A11))) -> GA | G11: =IF(E11="No Match","Review",IF(ISNUMBER(SEARCH(F11,E11)),"Likely Match","Review")) -> Likely Match
A12: Boston, MA | B12: Boston-Cambridge-Newton, MA-NH Metro Area | C12: High Confidence | D12: =LEFT(A12,FIND(",",A12)-1) -> Boston | E12: =IFERROR(INDEX(Census_Metro_List!$A:$A,MATCH(D12&"*",Census_Metro_List!$A:$A,0)),"No Match") -> Boston-Cambridge-Newton, MA-NH Metro Area | F12: =TRIM(RIGHT(A12,LEN(A12)-FIND(",",A12))) -> MA | G12: =IF(E12="No Match","Review",IF(ISNUMBER(SEARCH(F12,E12)),"Likely Match","Review")) -> Likely Match
A13: Phoenix, AZ | B13: Phoenix-Mesa-Chandler, AZ Metro Area | C13: High Confidence | D13: =LEFT(A13,FIND(",",A13)-1) -> Phoenix | E13: =IFERROR(INDEX(Census_Metro_List!$A:$A,MATCH(D13&"*",Census_Metro_List!$A:$A,0)),"No Match") -> Phoenix-Mesa-Chandler, AZ Metro Area | F13: =TRIM(RIGHT(A13,LEN(A13)-FIND(",",A13))) -> AZ | G13: =IF(E13="No Match","Review",IF(ISNUMBER(SEARCH(F13,E13)),"Likely Match","Review")) -> Likely Match
... A46: Richmond, VA | B46: Richmond, VA Metro Area | C46: High Confidence | D46: =LEFT(A46,FIND(",",A46)-1) -> Richmond | E46: =IFERROR(INDEX(Census_Metro_List!$A:$A,MATCH(D46&"*",Census_Metro_List!$A:$A,0)),"No Match") -> Richmond, VA Metro Area | F46: =TRIM(RIGHT(A46,LEN(A46)-FIND(",",A46))) -> VA | G46: =IF(E46="No Match","Review",IF(ISNUMBER(SEARCH(F46,E46)),"Likely Match","Review")) -> Likely Match
A47: Louisville, KY | C47: No Census Metro Match | D47: =LEFT(A47,FIND(",",A47)-1) -> Louisville | E47: =IFERROR(INDEX(Census_Metro_List!$A:$A,MATCH(D47&"*",Census_Metro_List!$A:$A,0)),"No Match") -> Louisville/Jefferson County, KY-IN Metro Area | F47: =TRIM(RIGHT(A47,LEN(A47)-FIND(",",A47))) -> KY | G47: =IF(E47="No Match","Review",IF(ISNUMBER(SEARCH(F47,E47)),"Likely Match","Review")) -> Likely Match
A48: New Orleans, LA | B48: New Orleans-Metairie, LA Metro Area | C48: High Confidence | D48: =LEFT(A48,FIND(",",A48)-1) -> New Orleans | E48: =IFERROR(INDEX(Census_Metro_List!$A:$A,MATCH(D48&"*",Census_Metro_List!$A:$A,0)),"No Match") -> New Orleans-Metairie, LA Metro Area | F48: =TRIM(RIGHT(A48,LEN(A48)-FIND(",",A48))) -> LA | G48: =IF(E48="No Match","Review",IF(ISNUMBER(SEARCH(F48,E48)),"Likely Match","Review")) -> Likely Match
A49: Salt Lake City, UT | B49: Salt Lake City-Murray, UT Metro Area | C49: High Confidence | D49: =LEFT(A49,FIND(",",A49)-1) -> Salt Lake City | E49: =IFERROR(INDEX(Census_Metro_List!$A:$A,MATCH(D49&"*",Census_Metro_List!$A:$A,0)),"No Match") -> Salt Lake City-Murray, UT Metro Area | F49: =TRIM(RIGHT(A49,LEN(A49)-FIND(",",A49))) -> UT | G49: =IF(E49="No Match","Review",IF(ISNUMBER(SEARCH(F49,E49)),"Likely Match","Review")) -> Likely Match
A50: Hartford, CT | B50: Hartford-West Hartford-East Hartford, CT Metro Area | C50: High Confidence | D50: =LEFT(A50,FIND(",",A50)-1) -> Hartford | E50: =IFERROR(INDEX(Census_Metro_List!$A:$A,MATCH(D50&"*",Census_Metro_List!$A:$A,0)),"No Match") -> Hartford-West Hartford-East Hartford, CT Metro Area | F50: =TRIM(RIGHT(A50,LEN(A50)-FIND(",",A50))) -> CT | G50: =IF(E50="No Match","Review",IF(ISNUMBER(SEARCH(F50,E50)),"Likely Match","Review")) -> Likely Match
A51: Buffalo, NY | B51: Buffalo-Cheektowaga, NY Metro Area | C51: High Confidence | D51: =LEFT(A51,FIND(",",A51)-1) -> Buffalo | E51: =IFERROR(INDEX(Census_Metro_List!$A:$A,MATCH(D51&"*",Census_Metro_List!$A:$A,0)),"No Match") -> Buffalo-Cheektowaga, NY Metro Area | F51: =TRIM(RIGHT(A51,LEN(A51)-FIND(",",A51))) -> NY | G51: =IF(E51="No Match","Review",IF(ISNUMBER(SEARCH(F51,E51)),"Likely Match","Review")) -> Likely Match
A52: Birmingham, AL | B52: Birmingham, AL Metro Area | C52: High Confidence | D52: =LEFT(A52,FIND(",",A52)-1) -> Birmingham | E52: =IFERROR(INDEX(Census_Metro_List!$A:$A,MATCH(D52&"*",Census_Metro_List!$A:$A,0)),"No Match") -> Birmingham, AL Metro Area | F52: =TRIM(RIGHT(A52,LEN(A52)-FIND(",",A52))) -> AL | G52: =IF(E52="No Match","Review",IF(ISNUMBER(SEARCH(F52,E52)),"Likely Match","Review")) -> Likely Match
A53: Rochester, NY | B53: Rochester, NY Metro Area | C53: High Confidence | D53: =LEFT(A53,FIND(",",A53)-1) -> Rochester | E53: =IFERROR(INDEX(Census_Metro_List!$A:$A,MATCH(D53&"*",Census_Metro_List!$A:$A,0)),"No Match") -> Rochester, MN Metro Area | F53: =TRIM(RIGHT(A53,LEN(A53)-FIND(",",A53))) -> NY | G53: =IF(E53="No Match","Review",IF(ISNUMBER(SEARCH(F53,E53)),"Likely Match","Review")) -> Review
A54: Grand Rapids, MI | B54: Grand Rapids-Wyoming-Kentwood, MI Metro Area | C54: High Confidence | D54: =LEFT(A54,FIND(",",A54)-1) -> Grand Rapids | E54: =IFERROR(INDEX(Census_Metro_List!$A:$A,MATCH(D54&"*",Census_Metro_List!$A:$A,0)),"No Match") -> Grand Rapids-Wyoming-Kentwood, MI Metro Area | F54: =TRIM(RIGHT(A54,LEN(A54)-FIND(",",A54))) -> MI | G54: =IF(E54="No Match","Review",IF(ISNUMBER(SEARCH(F54,E54)),"Likely Match","Review")) -> Likely Match
A55: Tucson, AZ | B55: Tucson, AZ Metro Area | C55: High Confidence | D55: =LEFT(A55,FIND(",",A55)-1) -> Tucson | E55: =IFERROR(INDEX(Census_Metro_List!$A:$A,MATCH(D55&"*",Census_Metro_List!$A:$A,0)),"No Match") -> Tucson, AZ Metro Area | F55: =TRIM(RIGHT(A55,LEN(A55)-FIND(",",A55))) -> AZ | G55: =IF(E55="No Match","Review",IF(ISNUMBER(SEARCH(F55,E55)),"Likely Match","Review")) -> Likely Match
A56: Urban Honolulu, HI | B56: Urban Honolulu, HI Metro Area | C56: High Confidence | D56: =LEFT(A56,FIND(",",A56)-1) -> Urban Honolulu | E56: =IFERROR(INDEX(Census_Metro_List!$A:$A,MATCH(D56&"*",Census_Metro_List!$A:$A,0)),"No Match") -> Urban Honolulu, HI Metro Area | F56: =TRIM(RIGHT(A56,LEN(A56)-FIND(",",A56))) -> HI | G56: =IF(E56="No Match","Review",IF(ISNUMBER(SEARCH(F56,E56)),"Likely Match","Review")) -> Likely Match
A57: Tulsa, OK | B57: Tulsa, OK Metro Area | C57: High Confidence | D57: =LEFT(A57,FIND(",",A57)-1) -> Tulsa | E57: =IFERROR(INDEX(Census_Metro_List!$A:$A,MATCH(D57&"*",Census_Metro_List!$A:$A,0)),"No Match") -> Tulsa, OK Metro Area | F57: =TRIM(RIGHT(A57,LEN(A57)-FIND(",",A57))) -> OK | G57: =IF(E57="No Match","Review",IF(ISNUMBER(SEARCH(F57,E57)),"Likely Match","Review")) -> Likely Match
A58: Fresno, CA | B58: Fresno, CA Metro Area | C58: High Confidence | D58: =LEFT(A58,FIND(",",A58)-1) -> Fresno | E58: =IFERROR(INDEX(Census_Metro_List!$A:$A,MATCH(D58&"*",Census_Metro_List!$A:$A,0)),"No Match") -> Fresno, CA Metro Area | F58: =TRIM(RIGHT(A58,LEN(A58)-FIND(",",A58))) -> CA | G58: =IF(E58="No Match","Review",IF(ISNUMBER(SEARCH(F58,E58)),"Likely Match","Review")) -> Likely Match
A59: Worcester, MA | B59: Worcester, MA Metro Area | C59: High Confidence | D59: =LEFT(A59,FIND(",",A59)-1) -> Worcester | E59: =IFERROR(INDEX(Census_Metro_List!$A:$A,MATCH(D59&"*",Census_Metro_List!$A:$A,0)),"No Match") -> Worcester, MA Metro Area | F59: =TRIM(RIGHT(A59,LEN(A59)-FIND(",",A59))) -> MA | G59: =IF(E59="No Match","Review",IF(ISNUMBER(SEARCH(F59,E59)),"Likely Match","Review")) -> Likely Match
... A222: Florence, SC | B222: Florence, SC Metro Area | C222: High Confidence | D222: =LEFT(A222,FIND(",",A222)-1) -> Florence | E222: =IFERROR(INDEX(Census_Metro_List!$A:$A,MATCH(D222&"*",Census_Metro_List!$A:$A,0)),"No Match") -> Florence, SC Metro Area | F222: =TRIM(RIGHT(A222,LEN(A222)-FIND(",",A222))) -> SC | G222: =IF(E222="No Match","Review",IF(ISNUMBER(SEARCH(F222,E222)),"Likely Match","Review")) -> Likely Match
A223: Hilo, HI | C223: No Census Metro Match | D223: =LEFT(A223,FIND(",",A223)-1) -> Hilo | E223: =IFERROR(INDEX(Census_Metro_List!$A:$A,MATCH(D223&"*",Census_Metro_List!$A:$A,0)),"No Match") -> No Match | F223: =TRIM(RIGHT(A223,LEN(A223)-FIND(",",A223))) -> HI | G223: =IF(E223="No Match","Review",IF(ISNUMBER(SEARCH(F223,E223)),"Likely Match","Review")) -> Review
A224: St. Cloud, MN | B224: St. Cloud, MN Metro Area | C224: High Confidence | D224: =LEFT(A224,FIND(",",A224)-1) -> St. Cloud | E224: =IFERROR(INDEX(Census_Metro_List!$A:$A,MATCH(D224&"*",Census_Metro_List!$A:$A,0)),"No Match") -> St. Cloud, MN Metro Area | F224: =TRIM(RIGHT(A224,LEN(A224)-FIND(",",A224))) -> MN | G224: =IF(E224="No Match","Review",IF(ISNUMBER(SEARCH(F224,E224)),"Likely Match","Review")) -> Likely Match
A225: Racine, WI | B225: Racine-Mount Pleasant, WI Metro Area | C225: High Confidence | D225: =LEFT(A225,FIND(",",A225)-1) -> Racine | E225: =IFERROR(INDEX(Census_Metro_List!$A:$A,MATCH(D225&"*",Census_Metro_List!$A:$A,0)),"No Match") -> Racine-Mount Pleasant, WI Metro Area | F225: =TRIM(RIGHT(A225,LEN(A225)-FIND(",",A225))) -> WI | G225: =IF(E225="No Match","Review",IF(ISNUMBER(SEARCH(F225,E225)),"Likely Match","Review")) -> Likely Match
A226: Bend, OR | B226: Bend, OR Metro Area | C226: High Confidence | D226: =LEFT(A226,FIND(",",A226)-1) -> Bend | E226: =IFERROR(INDEX(Census_Metro_List!$A:$A,MATCH(D226&"*",Census_Metro_List!$A:$A,0)),"No Match") -> Bend, OR Metro Area | F226: =TRIM(RIGHT(A226,LEN(A226)-FIND(",",A226))) -> OR | G226: =IF(E226="No Match","Review",IF(ISNUMBER(SEARCH(F226,E226)),"Likely Match","Review")) -> Likely Match
A227: Saginaw, MI | B227: Saginaw, MI Metro Area | C227: High Confidence | D227: =LEFT(A227,FIND(",",A227)-1) -> Saginaw | E227: =IFERROR(INDEX(Census_Metro_List!$A:$A,MATCH(D227&"*",Census_Metro_List!$A:$A,0)),"No Match") -> Saginaw, MI Metro Area | F227: =TRIM(RIGHT(A227,LEN(A227)-FIND(",",A227))) -> MI | G227: =IF(E227="No Match","Review",IF(ISNUMBER(SEARCH(F227,E227)),"Likely Match","Review")) -> Likely Match
A228: Warner Robins, GA | B228: Warner Robins, GA Metro Area | C228: High Confidence | D228: =LEFT(A228,FIND(",",A228)-1) -> Warner Robins | E228: =IFERROR(INDEX(Census_Metro_List!$A:$A,MATCH(D228&"*",Census_Metro_List!$A:$A,0)),"No Match") -> Warner Robins, GA Metro Area | F228: =TRIM(RIGHT(A228,LEN(A228)-FIND(",",A228))) -> GA | G228: =IF(E228="No Match","Review",IF(ISNUMBER(SEARCH(F228,E228)),"Likely Match","Review")) -> Likely Match
A229: Terre Haute, IN | B229: Terre Haute, IN Metro Area | C229: High Confidence | D229: =LEFT(A229,FIND(",",A229)-1) -> Terre Haute | E229: =IFERROR(INDEX(Census_Metro_List!$A:$A,MATCH(D229&"*",Census_Metro_List!$A:$A,0)),"No Match") -> Terre Haute, IN Metro Area | F229: =TRIM(RIGHT(A229,LEN(A229)-FIND(",",A229))) -> IN | G229: =IF(E229="No Match","Review",IF(ISNUMBER(SEARCH(F229,E229)),"Likely Match","Review")) -> Likely Match
A230: Torrington, CT | C230: No Census Metro Match | D230: =LEFT(A230,FIND(",",A230)-1) -> Torrington | E230: =IFERROR(INDEX(Census_Metro_List!$A:$A,MATCH(D230&"*",Census_Metro_List!$A:$A,0)),"No Match") -> No Match | F230: =TRIM(RIGHT(A230,LEN(A230)-FIND(",",A230))) -> CT | G230: =IF(E230="No Match","Review",IF(ISNUMBER(SEARCH(F230,E230)),"Likely Match","Review")) -> Review
A231: Punta Gorda, FL | B231: Punta Gorda, FL Metro Area | C231: High Confidence | D231: =LEFT(A231,FIND(",",A231)-1) -> Punta Gorda | E231: =IFERROR(INDEX(Census_Metro_List!$A:$A,MATCH(D231&"*",Census_Metro_List!$A:$A,0)),"No Match") -> Punta Gorda, FL Metro Area | F231: =TRIM(RIGHT(A231,LEN(A231)-FIND(",",A231))) -> FL | G231: =IF(E231="No Match","Review",IF(ISNUMBER(SEARCH(F231,E231)),"Likely Match","Review")) -> Likely Match
A232: Billings, MT | B232: Billings, MT Metro Area | C232: High Confidence | D232: =LEFT(A232,FIND(",",A232)-1) -> Billings | E232: =IFERROR(INDEX(Census_Metro_List!$A:$A,MATCH(D232&"*",Census_Metro_List!$A:$A,0)),"No Match") -> Billings, MT Metro Area | F232: =TRIM(RIGHT(A232,LEN(A232)-FIND(",",A232))) -> MT | G232: =IF(E232="No Match","Review",IF(ISNUMBER(SEARCH(F232,E232)),"Likely Match","Review")) -> Likely Match
A233: Redding, CA | B233: Redding, CA Metro Area | C233: High Confidence | D233: =LEFT(A233,FIND(",",A233)-1) -> Redding | E233: =IFERROR(INDEX(Census_Metro_List!$A:$A,MATCH(D233&"*",Census_Metro_List!$A:$A,0)),"No Match") -> Redding, CA Metro Area | F233: =TRIM(RIGHT(A233,LEN(A233)-FIND(",",A233))) -> CA | G233: =IF(E233="No Match","Review",IF(ISNUMBER(SEARCH(F233,E233)),"Likely Match","Review")) -> Likely Match
A234: Kingston, NY | B234: Kingston, NY Metro Area | C234: High Confidence | D234: =LEFT(A234,FIND(",",A234)-1) -> Kingston | E234: =IFERROR(INDEX(Census_Metro_List!$A:$A,MATCH(D234&"*",Census_Metro_List!$A:$A,0)),"No Match") -> Kingston, NY Metro Area | F234: =TRIM(RIGHT(A234,LEN(A234)-FIND(",",A234))) -> NY | G234: =IF(E234="No Match","Review",IF(ISNUMBER(SEARCH(F234,E234)),"Likely Match","Review")) -> Likely Match
...

Sheet Census_Metro_List
A1: Census Metro
A2: Abilene, TX Metro Area
A3: Aguadilla, PR Metro Area
A4: Akron, OH Metro Area
A5: Albany, GA Metro Area
A6: Albany, OR Metro Area
A7: Albany-Schenectady-Troy, NY Metro Area
A8: Albuquerque, NM Metro Area
A9: Alexandria, LA Metro Area
A10: Allentown-Bethlehem-Easton, PA-NJ Metro Area
A11: Altoona, PA Metro Area
A12: Amarillo, TX Metro Area
... A394: Yuma, AZ Metro Area

Sheet Census_Unmatched
A1: Census Metro | B1: Suggested Zillow Candidate | C1: Review Note
A2: Aguadilla, PR Metro Area | C2: No reliable Zillow alias found
A3: Amherst Town-Northampton, MA Metro Area | C3: No reliable Zillow alias found
A4: Arecibo, PR Metro Area | C4: No reliable Zillow alias found
A5: Dayton-Kettering-Beavercreek, OH Metro Area | C5: No reliable Zillow alias found
A6: Guayama, PR Metro Area | C6: No reliable Zillow alias found
A7: Kenosha, WI Metro Area | C7: No reliable Zillow alias found
A8: Kiryas Joel-Poughkeepsie-Newburgh, NY Metro Area | C8: No reliable Zillow alias found
A9: Lexington Park, MD Metro Area | C9: No reliable Zillow alias found
A10: Louisville/Jefferson County, KY-IN Metro Area | B10: Louisville, KY | C10: Strong alias candidate — verify
A11: Mayagüez, PR Metro Area | C11: No reliable Zillow alias found
A12: Ponce, PR Metro Area | C12: No reliable Zillow alias found
A13: Prescott Valley-Prescott, AZ Metro Area | C13: No reliable Zillow alias found
A14: San Juan-Bayamón-Caguas, PR Metro Area | C14: No reliable Zillow alias found
A15: Slidell-Mandeville-Covington, LA Metro Area | C15: No reliable Zillow alias found
A16: Waterbury-Shelton, CT Metro Area | C16: No reliable Zillow alias found
A17: Wildwood-The Villages, FL Metro Area | B17: The Villages, FL | C17: Strong alias candidate — verify
